Workbook
Name CÓRDOBA: CORDOBA[CÓRDOBA]
Name R_AMAZONÍA: REGION_AMAZONIA[R_AMAZONÍA]
Name R_ANDINA: REGION_ANDINA[R_ANDINA]
Name R_CARIBE: REGION_CARIBE[R_CARIBE]
Name R_INSULAR: REGION_INSULAR[R_INSULAR]
Name R_ORINOQUIA: REGION_ORINOQUIA[R_ORINOQUIA]
Name R_PACÍFICA: REGION_PACIFICA[R_PACÍFICA]
Name TIEMPO_PARTICIPACION: Tabla47[#All]

Sheet TABLA
A1: CONSOLIDADO INTERNACIONAL DE VOLUNTARIADO CERTIFICADO POR LOS LIDERES DE CADA LUGAR O ÁREA - FHSYL DIRECCIÓN FINANCIERA
A2: UBICACIÓN GEOGRÁFICA | F2: IDENTIFICACIÓN DEL VOLUNTARIO | J2: DATOS DE CONTACTO DEL VOLUNTARIO | N2: ASIGNACIÓN Y TIEMPO DEL VOLUNTARIO EN LA FUNDACIÓN | S2: TIEMPO DE PARTICIPACION | U2: VALORACIÓN DE LA GESTIÓN DEL VOLUNTARIO (Anote el valor que corresponda de acuerdo con la escala de valoración y la descripción de cada nivel a la derecha, columnas V,W,X,Y) | Z2: IDENTIFICACIÓN DEL LÍDER DE VOLUNTARIADO QUIEN REALIZÓ LA VALORACIÓN | AC2: VALORACIÓN DE LA GESTIÓN DEL VOLUNTARIO
A3: CONTINENTE | B3: PAÍS | C3: REGIÓN | D3: DEPARTAMENTO | E3: MUNICIPIO | F3: NOMBRE COMPLETO | G3: APELLIDOS | H3: TIPO DE DOCUMENTO DE IDENTIDAD | I3: NUMERO DE DOCUMENTO DE IDENTIDAD | J3: DIRECCIÓN | K3: TELÉFONO FIJO/CELULAR | L3: CORREO ELECTRÓNICO | M3: ASIGNACIÓN ACTUAL (Rol y lugar asignado) | N3: VALORACIÓN POR ASIGNACIÓN | O3: PUNTAJE | P3: FECHA DE INICIO VOLUNTARIADO (día/mes/año) | Q3: FECHA FINAL (si aplica) o fecha actual | R3: TIEMPO TOTAL (en meses) | S3: TIEMPO Participación efectiva y continuada en las actividades de voluntariado) | T3: PUNTAJE | U3: PARTICIPACIÓN (En el Altar de Oración 24/7, en actividades para la unidad espiritual, en capacitaciones, en gestión social, en planeación) | V3: PUNTAJE | W3: COMPROMISO (Disposición y disponibilidad para asumir responsabilidades y entregar resultados de manera oportuna y eficaz) | X3: PUNTAJE | Y3: PUNTAJE FINAL | Z3: NOMBRE DEL LÍDER VOLUNTARIO | AA3: ASIGNACIÓN DEL LÍDER VOLUNTARIO Y LUGAR ASIGNADO | AC3: PARTICIPACIÓN (En el Altar de Oración 24/7, en actividades para la unidad espiritual, en capacitaciones, en gestión social, en planeación) | AD3: PUNTAJE | AE3: COMPROMISO (Disposición y disponibilidad para asumir responsabilidades y entregar resultados de manera oportuna y eficaz) | AF3: PUNTAJE | AH3: Diferentes tipo de IDENTIFICACIÓN | AI3: PAÍS
A4: SUR AMÉRICA | B4: COLOMBIA | C4: R_CARIBE | D4: ATLÁNTICO | E4: BARRANQUILLA | K4: 3104303845 | L4: mateorocha@yaoo.com | M4: Asistente Administrativo | N4: Secretarias y personal administrativo gestion Global | O4: =IF(N4="","",VLOOKUP(N4,ROLES!B:C,2,FALSE)) -> 4.6 | P4: 44948 | Q4: 46098 | R4: =DATEDIF(P4,Q4,"m") -> 37 | S4: Entre 36 meses y 47 meses | T4: =IF(S4="","",VLOOKUP(S4,VALORACION!F:G,2,FALSE)) -> 4 | U4: Participación sobresaliente, liderazgo activo | V4: =IF(U4="","",VLOOKUP(U4,ROLES!G:H,2,FALSE)) -> 9 | W4: Compromiso ejemplar, referente para otros | X4: =IF(W4="","",VLOOKUP(W4,ROLES!I:J,2,FALSE)) -> 9 | Y4: =(VALUE(O4)+VALUE(V4)+VALUE(X4)+VALUE(T4))/3 -> 8.8666667 | Z4: Ibeth Puerta Gutierrez | AA4: Subfinanciero | AH4: C.C | AI4: Colombia
A5: SUR AMÉRICA | B5: COLOMBIA | O5: =IF(N5="","",VLOOKUP(N5,ROLES!B:C,2,FALSE)) | R5: =DATEDIF(P5,Q5,"m") -> 0 | T5: =IF(S5="","",VLOOKUP(S5,VALORACION!F:G,2,FALSE)) | V5: =IF(U5="","",VLOOKUP(U5,ROLES!G:H,2,FALSE)) | X5: =IF(W5="","",VLOOKUP(W5,ROLES!I:J,2,FALSE)) | Y5: =(VALUE(O5)+VALUE(V5)+VALUE(X5)+VALUE(T5))/3 -> #VALUE! | AH5: INE | AI5: México
O6: =IF(N6="","",VLOOKUP(N6,ROLES!B:C,2,FALSE)) | R6: =DATEDIF(P6,Q6,"m") -> 0 | T6: =IF(S6="","",VLOOKUP(S6,VALORACION!F:G,2,FALSE)) | V6: =IF(U6="","",VLOOKUP(U6,ROLES!G:H,2,FALSE)) | X6: =IF(W6="","",VLOOKUP(W6,ROLES!I:J,2,FALSE)) | Y6: =(VALUE(O6)+VALUE(V6)+VALUE(X6)+VALUE(T6))/3 -> #VALUE! | AC6: Participación excepcional, motor clave del equipo | AD6: 10 | AE6: Compromiso excepcional, modelo de fidelidad y entrega | AF6: 10 | AH6: DNI | AI6: Argentina
O7: =IF(N7="","",VLOOKUP(N7,ROLES!B:C,2,FALSE)) | R7: =DATEDIF(P7,Q7,"m") -> 0 | T7: =IF(S7="","",VLOOKUP(S7,VALORACION!F:G,2,FALSE)) | V7: =IF(U7="","",VLOOKUP(U7,ROLES!G:H,2,FALSE)) | X7: =IF(W7="","",VLOOKUP(W7,ROLES!I:J,2,FALSE)) | Y7: =(VALUE(O7)+VALUE(V7)+VALUE(X7)+VALUE(T7))/3 -> #VALUE! | AC7: Participación sobresaliente, liderazgo activo | AD7: 9 | AE7: Compromiso ejemplar, referente para otros | AF7: 9 | AH7: C.I | AI7: chile
O8: =IF(N8="","",VLOOKUP(N8,ROLES!B:C,2,FALSE)) | R8: =DATEDIF(P8,Q8,"m") -> 0 | T8: =IF(S8="","",VLOOKUP(S8,VALORACION!F:G,2,FALSE)) | V8: =IF(U8="","",VLOOKUP(U8,ROLES!G:H,2,FALSE)) | X8: =IF(W8="","",VLOOKUP(W8,ROLES!I:J,2,FALSE)) | Y8: =(VALUE(O8)+VALUE(V8)+VALUE(X8)+VALUE(T8))/3 -> #VALUE! | AC8: Participación alta, proactiva y comprometida | AD8: 8 | AE8: Compromiso alto, constante y fiel | AF8: 8 | AH8: CPF | AI8: Brasil
O9: =IF(N9="","",VLOOKUP(N9,ROLES!B:C,2,FALSE)) | R9: =DATEDIF(P9,Q9,"m") -> 0 | T9: =IF(S9="","",VLOOKUP(S9,VALORACION!F:G,2,FALSE)) | V9: =IF(U9="","",VLOOKUP(U9,ROLES!G:H,2,FALSE)) | X9: =IF(W9="","",VLOOKUP(W9,ROLES!I:J,2,FALSE)) | Y9: =(VALUE(O9)+VALUE(V9)+VALUE(X9)+VALUE(T9))/3 -> #VALUE! | AC9: Buena participación, colabora con constancia | AD9: 7 | AE9: Buen compromiso, responsable y confiable | AF9: 7 | AH9: SSN | AI9: EEUU
O10: =IF(N10="","",VLOOKUP(N10,ROLES!B:C,2,FALSE)) | R10: =DATEDIF(P10,Q10,"m") -> 0 | T10: =IF(S10="","",VLOOKUP(S10,VALORACION!F:G,2,FALSE)) | V10: =IF(U10="","",VLOOKUP(U10,ROLES!G:H,2,FALSE)) | X10: =IF(W10="","",VLOOKUP(W10,ROLES!I:J,2,FALSE)) | Y10: =(VALUE(O10)+VALUE(V10)+VALUE(X10)+VALUE(T10))/3 -> #VALUE! | AC10: Participa activamente en algunas actividades | AD10: 6 | AE10: Compromiso aceptable, responde cuando se le solicita | AF10: 6 | AH10: LICENCIA DE CONDUCIR | AI10: CANADÁ
O11: =IF(N11="","",VLOOKUP(N11,ROLES!B:C,2,FALSE)) | R11: =DATEDIF(P11,Q11,"m") -> 0 | T11: =IF(S11="","",VLOOKUP(S11,VALORACION!F:G,2,FALSE)) | V11: =IF(U11="","",VLOOKUP(U11,ROLES!G:H,2,FALSE)) | X11: =IF(W11="","",VLOOKUP(W11,ROLES!I:J,2,FALSE)) | Y11: =(VALUE(O11)+VALUE(V11)+VALUE(X11)+VALUE(T11))/3 -> #VALUE! | AC11: Participación regular, cumple lo básico | AD11: 5 | AE11: Compromiso básico, cumple lo mínimo esperado | AF11: 5
O12: =IF(N12="","",VLOOKUP(N12,ROLES!B:C,2,FALSE)) | R12: =DATEDIF(P12,Q12,"m") -> 0 | T12: =IF(S12="","",VLOOKUP(S12,VALORACION!F:G,2,FALSE)) | V12: =IF(U12="","",VLOOKUP(U12,ROLES!G:H,2,FALSE)) | X12: =IF(W12="","",VLOOKUP(W12,ROLES!I:J,2,FALSE)) | Y12: =(VALUE(O12)+VALUE(V12)+VALUE(X12)+VALUE(T12))/3 -> #VALUE! | AC12: Participa ocasionalmente, requiere motivación externa | AD12: 4 | AE12: Compromiso débil, cumple parcialmente | AF12: 4
O13: =IF(N13="","",VLOOKUP(N13,ROLES!B:C,2,FALSE)) | R13: =DATEDIF(P13,Q13,"m") -> 0 | T13: =IF(S13="","",VLOOKUP(S13,VALORACION!F:G,2,FALSE)) | V13: =IF(U13="","",VLOOKUP(U13,ROLES!G:H,2,FALSE)) | X13: =IF(W13="","",VLOOKUP(W13,ROLES!I:J,2,FALSE)) | Y13: =(VALUE(O13)+VALUE(V13)+VALUE(X13)+VALUE(T13))/3 -> #VALUE! | AC13: Participación baja e inconstante | AD13: 3 | AE13: Compromiso bajo, requiere constante supervisión | AF13: 3
O14: =IF(N14="","",VLOOKUP(N14,ROLES!B:C,2,FALSE)) | R14: =DATEDIF(P14,Q14,"m") -> 0 | T14: =IF(S14="","",VLOOKUP(S14,VALORACION!F:G,2,FALSE)) | V14: =IF(U14="","",VLOOKUP(U14,ROLES!G:H,2,FALSE)) | X14: =IF(W14="","",VLOOKUP(W14,ROLES!I:J,2,FALSE)) | Y14: =(VALUE(O14)+VALUE(V14)+VALUE(X14)+VALUE(T14))/3 -> #VALUE! | AC14: Participa muy rara vez, mínima interacción | AD14: 2 | AE14: Compromiso deficiente, irresponsabilidad frecuente | AF14: 2
O15: =IF(N15="","",VLOOKUP(N15,ROLES!B:C,2,FALSE)) | R15: =DATEDIF(P15,Q15,"m") -> 0 | T15: =IF(S15="","",VLOOKUP(S15,VALORACION!F:G,2,FALSE)) | V15: =IF(U15="","",VLOOKUP(U15,ROLES!G:H,2,FALSE)) | X15: =IF(W15="","",VLOOKUP(W15,ROLES!I:J,2,FALSE)) | Y15: =(VALUE(O15)+VALUE(V15)+VALUE(X15)+VALUE(T15))/3 -> #VALUE! | AC15: Casi nunca participa, ausencias constantes | AD15: 1 | AE15: Compromiso muy bajo evidenciado en incumplimientos reiterados | AF15: 1
O16: =IF(N16="","",VLOOKUP(N16,ROLES!B:C,2,FALSE)) | R16: =DATEDIF(P16,Q16,"m") -> 0 | T16: =IF(S16="","",VLOOKUP(S16,VALORACION!F:G,2,FALSE)) | V16: =IF(U16="","",VLOOKUP(U16,ROLES!G:H,2,FALSE)) | X16: =IF(W16="","",VLOOKUP(W16,ROLES!I:J,2,FALSE)) | Y16: =(VALUE(O16)+VALUE(V16)+VALUE(X16)+VALUE(T16))/3 -> #VALUE!
O17: =IF(N17="","",VLOOKUP(N17,ROLES!B:C,2,FALSE)) | R17: =DATEDIF(P17,Q17,"m") -> 0 | T17: =IF(S17="","",VLOOKUP(S17,VALORACION!F:G,2,FALSE)) | V17: =IF(U17="","",VLOOKUP(U17,ROLES!G:H,2,FALSE)) | X17: =IF(W17="","",VLOOKUP(W17,ROLES!I:J,2,FALSE)) | Y17: =(VALUE(O17)+VALUE(V17)+VALUE(X17)+VALUE(T17))/3 -> #VALUE!
O18: =IF(N18="","",VLOOKUP(N18,ROLES!B:C,2,FALSE)) | R18: =DATEDIF(P18,Q18,"m") -> 0 | T18: =IF(S18="","",VLOOKUP(S18,VALORACION!F:G,2,FALSE)) | V18: =IF(U18="","",VLOOKUP(U18,ROLES!G:H,2,FALSE)) | X18: =IF(W18="","",VLOOKUP(W18,ROLES!I:J,2,FALSE)) | Y18: =(VALUE(O18)+VALUE(V18)+VALUE(X18)+VALUE(T18))/3 -> #VALUE!
O19: =IF(N19="","",VLOOKUP(N19,ROLES!B:C,2,FALSE)) | R19: =DATEDIF(P19,Q19,"m") -> 0 | T19: =IF(S19="","",VLOOKUP(S19,VALORACION!F:G,2,FALSE)) | V19: =IF(U19="","",VLOOKUP(U19,ROLES!G:H,2,FALSE)) | X19: =IF(W19="","",VLOOKUP(W19,ROLES!I:J,2,FALSE)) | Y19: =(VALUE(O19)+VALUE(V19)+VALUE(X19)+VALUE(T19))/3 -> #VALUE!
O20: =IF(N20="","",VLOOKUP(N20,ROLES!B:C,2,FALSE)) | R20: =DATEDIF(P20,Q20,"m") -> 0 | T20: =IF(S20="","",VLOOKUP(S20,VALORACION!F:G,2,FALSE)) | V20: =IF(U20="","",VLOOKUP(U20,ROLES!G:H,2,FALSE)) | X20: =IF(W20="","",VLOOKUP(W20,ROLES!I:J,2,FALSE)) | Y20: =(VALUE(O20)+VALUE(V20)+VALUE(X20)+VALUE(T20))/3 -> #VALUE!
O21: =IF(N21="","",VLOOKUP(N21,ROLES!B:C,2,FALSE)) | R21: =DATEDIF(P21,Q21,"m") -> 0 | T21: =IF(S21="","",VLOOKUP(S21,VALORACION!F:G,2,FALSE)) | V21: =IF(U21="","",VLOOKUP(U21,ROLES!G:H,2,FALSE)) | X21: =IF(W21="","",VLOOKUP(W21,ROLES!I:J,2,FALSE)) | Y21: =(VALUE(O21)+VALUE(V21)+VALUE(X21)+VALUE(T21))/3 -> #VALUE!
O22: =IF(N22="","",VLOOKUP(N22,ROLES!B:C,2,FALSE)) | R22: =DATEDIF(P22,Q22,"m") -> 0 | T22: =IF(S22="","",VLOOKUP(S22,VALORACION!F:G,2,FALSE)) | V22: =IF(U22="","",VLOOKUP(U22,ROLES!G:H,2,FALSE)) | X22: =IF(W22="","",VLOOKUP(W22,ROLES!I:J,2,FALSE)) | Y22: =(VALUE(O22)+VALUE(V22)+VALUE(X22)+VALUE(T22))/3 -> #VALUE!
O23: =IF(N23="","",VLOOKUP(N23,ROLES!B:C,2,FALSE)) | R23: =DATEDIF(P23,Q23,"m") -> 0 | T23: =IF(S23="","",VLOOKUP(S23,VALORACION!F:G,2,FALSE)) | V23: =IF(U23="","",VLOOKUP(U23,ROLES!G:H,2,FALSE)) | X23: =IF(W23="","",VLOOKUP(W23,ROLES!I:J,2,FALSE)) | Y23: =(VALUE(O23)+VALUE(V23)+VALUE(X23)+VALUE(T23))/3 -> #VALUE!
O24: =IF(N24="","",VLOOKUP(N24,ROLES!B:C,2,FALSE)) | R24: =DATEDIF(P24,Q24,"m") -> 0 | T24: =IF(S24="","",VLOOKUP(S24,VALORACION!F:G,2,FALSE)) | V24: =IF(U24="","",VLOOKUP(U24,ROLES!G:H,2,FALSE)) | X24: =IF(W24="","",VLOOKUP(W24,ROLES!I:J,2,FALSE)) | Y24: =(VALUE(O24)+VALUE(V24)+VALUE(X24)+VALUE(T24))/3 -> #VALUE!
O25: =IF(N25="","",VLOOKUP(N25,ROLES!B:C,2,FALSE)) | R25: =DATEDIF(P25,Q25,"m") -> 0 | T25: =IF(S25="","",VLOOKUP(S25,VALORACION!F:G,2,FALSE)) | V25: =IF(U25="","",VLOOKUP(U25,ROLES!G:H,2,FALSE)) | X25: =IF(W25="","",VLOOKUP(W25,ROLES!I:J,2,FALSE)) | Y25: =(VALUE(O25)+VALUE(V25)+VALUE(X25)+VALUE(T25))/3 -> #VALUE!
O26: =IF(N26="","",VLOOKUP(N26,ROLES!B:C,2,FALSE)) | R26: =DATEDIF(P26,Q26,"m") -> 0 | T26: =IF(S26="","",VLOOKUP(S26,VALORACION!F:G,2,FALSE)) | V26: =IF(U26="","",VLOOKUP(U26,ROLES!G:H,2,FALSE)) | X26: =IF(W26="","",VLOOKUP(W26,ROLES!I:J,2,FALSE)) | Y26: =(VALUE(O26)+VALUE(V26)+VALUE(X26)+VALUE(T26))/3 -> #VALUE!
O27: =IF(N27="","",VLOOKUP(N27,ROLES!B:C,2,FALSE)) | R27: =DATEDIF(P27,Q27,"m") -> 0 | T27: =IF(S27="","",VLOOKUP(S27,VALORACION!F:G,2,FALSE)) | V27: =IF(U27="","",VLOOKUP(U27,ROLES!G:H,2,FALSE)) | X27: =IF(W27="","",VLOOKUP(W27,ROLES!I:J,2,FALSE)) | Y27: =(VALUE(O27)+VALUE(V27)+VALUE(X27)+VALUE(T27))/3 -> #VALUE!
... O783: =IF(N783="","",VLOOKUP(N783,ROLES!B:C,2,FALSE)) | R783: =DATEDIF(P783,Q783,"m") -> 0 | T783: =IF(S783="","",VLOOKUP(S783,VALORACION!F:G,2,FALSE)) | V783: =IF(U783="","",VLOOKUP(U783,ROLES!G:H,2,FALSE)) | X783: =IF(W783="","",VLOOKUP(W783,ROLES!I:J,2,FALSE)) | Y783: =(VALUE(O783)+VALUE(V783)+VALUE(X783)+VALUE(T783))/3 -> #VALUE!
O784: =IF(N784="","",VLOOKUP(N784,ROLES!B:C,2,FALSE)) | R784: =DATEDIF(P784,Q784,"m") -> 0 | T784: =IF(S784="","",VLOOKUP(S784,VALORACION!F:G,2,FALSE)) | V784: =IF(U784="","",VLOOKUP(U784,ROLES!G:H,2,FALSE)) | Y784: =(VALUE(O784)+VALUE(V784)+VALUE(X784)+VALUE(T784))/3 -> #VALUE!
O785: =IF(N785="","",VLOOKUP(N785,ROLES!B:C,2,FALSE)) | R785: =DATEDIF(P785,Q785,"m") -> 0 | T785: =IF(S785="","",VLOOKUP(S785,VALORACION!F:G,2,FALSE)) | V785: =IF(U785="","",VLOOKUP(U785,ROLES!G:H,2,FALSE)) | Y785: =(VALUE(O785)+VALUE(V785)+VALUE(X785)+VALUE(T785))/3 -> #VALUE!
O786: =IF(N786="","",VLOOKUP(N786,ROLES!B:C,2,FALSE)) | R786: =DATEDIF(P786,Q786,"m") -> 0 | T786: =IF(S786="","",VLOOKUP(S786,VALORACION!F:G,2,FALSE)) | V786: =IF(U786="","",VLOOKUP(U786,ROLES!G:H,2,FALSE)) | Y786: =(VALUE(O786)+VALUE(V786)+VALUE(X786)+VALUE(T786))/3 -> #VALUE!
O787: =IF(N787="","",VLOOKUP(N787,ROLES!B:C,2,FALSE)) | R787: =DATEDIF(P787,Q787,"m") -> 0 | T787: =IF(S787="","",VLOOKUP(S787,VALORACION!F:G,2,FALSE)) | V787: =IF(U787="","",VLOOKUP(U787,ROLES!G:H,2,FALSE)) | Y787: =(VALUE(O787)+VALUE(V787)+VALUE(X787)+VALUE(T787))/3 -> #VALUE!
O788: =IF(N788="","",VLOOKUP(N788,ROLES!B:C,2,FALSE)) | R788: =DATEDIF(P788,Q788,"m") -> 0 | T788: =IF(S788="","",VLOOKUP(S788,VALORACION!F:G,2,FALSE)) | V788: =IF(U788="","",VLOOKUP(U788,ROLES!G:H,2,FALSE)) | Y788: =(VALUE(O788)+VALUE(V788)+VALUE(X788)+VALUE(T788))/3 -> #VALUE!
O789: =IF(N789="","",VLOOKUP(N789,ROLES!B:C,2,FALSE)) | R789: =DATEDIF(P789,Q789,"m") -> 0 | T789: =IF(S789="","",VLOOKUP(S789,VALORACION!F:G,2,FALSE)) | V789: =IF(U789="","",VLOOKUP(U789,ROLES!G:H,2,FALSE)) | Y789: =(VALUE(O789)+VALUE(V789)+VALUE(X789)+VALUE(T789))/3 -> #VALUE!
O790: =IF(N790="","",VLOOKUP(N790,ROLES!B:C,2,FALSE)) | R790: =DATEDIF(P790,Q790,"m") -> 0 | T790: =IF(S790="","",VLOOKUP(S790,VALORACION!F:G,2,FALSE)) | V790: =IF(U790="","",VLOOKUP(U790,ROLES!G:H,2,FALSE)) | Y790: =(VALUE(O790)+VALUE(V790)+VALUE(X790)+VALUE(T790))/3 -> #VALUE!
O791: =IF(N791="","",VLOOKUP(N791,ROLES!B:C,2,FALSE)) | R791: =DATEDIF(P791,Q791,"m") -> 0 | T791: =IF(S791="","",VLOOKUP(S791,VALORACION!F:G,2,FALSE)) | V791: =IF(U791="","",VLOOKUP(U791,ROLES!G:H,2,FALSE)) | Y791: =(VALUE(O791)+VALUE(V791)+VALUE(X791)+VALUE(T791))/3 -> #VALUE!
O792: =IF(N792="","",VLOOKUP(N792,ROLES!B:C,2,FALSE)) | R792: =DATEDIF(P792,Q792,"m") -> 0 | T792: =IF(S792="","",VLOOKUP(S792,VALORACION!F:G,2,FALSE)) | V792: =IF(U792="","",VLOOKUP(U792,ROLES!G:H,2,FALSE)) | Y792: =(VALUE(O792)+VALUE(V792)+VALUE(X792)+VALUE(T792))/3 -> #VALUE!
O793: =IF(N793="","",VLOOKUP(N793,ROLES!B:C,2,FALSE)) | R793: =DATEDIF(P793,Q793,"m") -> 0 | T793: =IF(S793="","",VLOOKUP(S793,VALORACION!F:G,2,FALSE)) | V793: =IF(U793="","",VLOOKUP(U793,ROLES!G:H,2,FALSE)) | Y793: =(VALUE(O793)+VALUE(V793)+VALUE(X793)+VALUE(T793))/3 -> #VALUE!
O794: =IF(N794="","",VLOOKUP(N794,ROLES!B:C,2,FALSE)) | R794: =DATEDIF(P794,Q794,"m") -> 0 | T794: =IF(S794="","",VLOOKUP(S794,VALORACION!F:G,2,FALSE)) | V794: =IF(U794="","",VLOOKUP(U794,ROLES!G:H,2,FALSE)) | Y794: =(VALUE(O794)+VALUE(V794)+VALUE(X794)+VALUE(T794))/3 -> #VALUE!
O795: =IF(N795="","",VLOOKUP(N795,ROLES!B:C,2,FALSE)) | R795: =DATEDIF(P795,Q795,"m") -> 0 | T795: =IF(S795="","",VLOOKUP(S795,VALORACION!F:G,2,FALSE)) | V795: =IF(U795="","",VLOOKUP(U795,ROLES!G:H,2,FALSE)) | Y795: =(VALUE(O795)+VALUE(V795)+VALUE(X795)+VALUE(T795))/3 -> #VALUE!
...

Sheet ROLES
A1: NIVELES DE GESTIÓN | B1: ROL O ASIGNACION (Impacto de la gestión en los resultados globales de la Fundación) | C1: PUNTAJE | E1: TIEMPO Participación efectiva y continuada en las actividades de voluntariado) | F1: PUNTAJE | G1: PARTICIPACIÓN (En el Altar de Oración 24/7, en actividades para la unidad espiritual, en capacitaciones, en gestión social, en planeación) | H1: PUNTAJE | I1: COMPROMISO (Disposición y disponibilidad para asumir responsabiloidades y entregar resultados de manera oportuna y eficaz) | J1: PUNTAJE
A3: Gobierno y Gestión Estratégica Global Gobierno corporativo y supervisión estratégica, alta dirección, alto nivel de decisiones, alto impacto en gestión. Responsabilidad por resultados globales: Transversal a TODOS las Áreas, Programas y Proyectos en TODOS los continentes | B3: Presidente-Representante Legal | C3: 10 | E3: 10 años o más Mas de 120 meses | F3: 10 | G3: Participación excepcional, motor clave del equipo | H3: 10 | I3: Compromiso excepcional, modelo de fidelidad y entrega | J3: 10
B4: Miembros Junta Directiva, Comité de cumplimiento, Ética y Riesgos | C4: 9.5
B5: Directores Gestión Financiera, Director Jurídico, Directora Gestión Administrativa y de Logísitica, Cancilleres, Director Proyectos Especiales | E5: 120
E6: Entre 8 y 10 años | F6: 9 | G6: Participación sobresaliente, liderazgo activo | H6: 9 | I6: Compromiso ejemplar, referente para otros | J6: 9
B7: Subdirectores Gestión Financiera Internacional, Jurídica, Directora Gestión Administrativa y de Logísitica, Cancilleres, Director Proyectos Especiales; Proyectos Especiales | C7: 9.3 | E7: Entre 96 y 120 meses
A8: Direcciones Programáticas y Áreas de Gestión Internacional Máxima autoridad operacional, Diseño de políticas, definición de indicadores y estándares de calidad. Responsabilidad por resultados de UN programa en TODOS los continentes | B8: Directores Programas Salvación Mundial y Misión de Paz y Psicosocial, Areas de Infraestructura, Comunicaciones y Relaciones Corporativas, Proyectos y otras | C8: 9 | E8: Entre 7 y 8 años | F8: 8 | G8: Participación alta, proactiva y comprometida | H8: 8 | I8: Compromiso alto, constante y fiel | J8: 8
E9: Entre 84 y 95 meses
B10: Sudirectores de Programas y Áreas: Programas Salvación Mundial y Misión de Paz y Psicosocial, Areas de Infraestructura, Comunicaciones y Relaciones Corporativas, Proyectos y otras | C10: 8.8 | E10: Entre 6 y 7 años | F10: 7 | G10: Buena participación, colabora con constancia | H10: 7 | I10: Buen compromiso, responsable y confiable | J10: 7
E11: Entre 72 y 83 meses
A12: Direcciones de Programas en Continentes Estrategia de intervención y supervisión en el grupo de países que conforman la macroregión. Responsabilidad por resultados de UN programa en UN continente o en UNA macroregión específica: Suramérica, Europa Central, Africa ...) | B12: Directores Programas y Áreas: Salvación Mundial y Misión de Paz y Psicosocial, Areas de Infraestructura, Comunicaciones y Relaciones Corporativas, Proyectos y otras | C12: 8.5 | E12: Entre 5 y 6 años | F12: 6 | G12: Participa activamente en algunas actividades | H12: 6 | I12: Compromiso aceptable, responde cuando se le solicita | J12: 6
B13: Subdirectores Programas y Áreas Salvación Mundial y Misión de Paz y Psicosocial, Areas de Infraestructura, Comunicaciones y Relaciones Corporativas, Proyectos y otras | C13: 8.3 | E13: Entre 60 y 71 meses | G13: Participación regular, cumple lo básico | H13: 5 | I13: Compromiso básico, cumple lo mínimo esperado | J13: 5
A14: Dirección Ejecutiva Nacional Máximo nivel de autoridad por país, gestión de proyectos y presupuestos. Responsabilidad por resultados de TODOS los programas y proyectos implementados en UN país específico), ) | B14: Directores de país. Gestión integral del país | C14: 8 | E14: Entre 4 y 5 años | F14: 5 | G14: Participa ocasionalmente, requiere motivación externa | H14: 4 | I14: Compromiso débil, cumple parcialmente | J14: 4
B15: Subdirectores de país (donde aplique). Seguimiento a la Operación Nacional | C15: 7.8 | E15: Entre 48 y 59 meses
B16: Directores nacionales de áreas funcionales, Embajadores nacionales, Directores de Programas nacionales, directores espirituales, capeyanes, Director Proyecto ARCA | C16: 7.5 | E16: Entre 3 y 4 años | F16: 4 | G16: Participación baja e inconstante | H16: 3 | I16: Compromiso bajo, requiere constante supervisión | J16: 3
B17: Subdirectores de áreas y programas nacionales, Proyecto ARCA | C17: 7.3 | E17: Entre 36 y 47 meses | G17: Participa muy rara vez, mínima interacción | H17: 2 | I17: Compromiso deficiente, irresponsabilidad frecuente | J17: 2
A18: Dirección Ejecutiva Región Supervisión de Programas y proyectos y presupuestos: Responsabilidad por resultados en TODOS los programas y proyectos implementados en los departamentos/estados que conforman UNA región específica en un país | B18: Directores: Gestión integral de los departamentos/estados agrupados | C18: 7 | E18: Entre 2 y 3 años | F18: 3
B19: Subdirectores Regionales. Seguimiento a la operación regional | C19: 6.8 | E19: Entre 24 y 35 meses | G19: Casi nunca participa, ausencias constantes | H19: 1 | I19: Compromiso muy bajo evidenciado en incumplimientos reiterados | J19: 1
B20: Directores de Programas y áreas. Seguimiento a las operaciones (Proyectos, salud, educación, infraestructura, Talento Humano, comunicaciones, Psicosocial, directores espirituales, capeyanes, etc… ) | C20: 6.6 | E20: Entre 1 y 2 años | F20: 2
A21: Equipo de profesionales vinculados a la Gestión Global Responsabilidad por los macroprocesos de la gestión global en TODOS los continentes | B21: Equipo de Profesionales con tareas en Presidencia, Junta Directiva, Gestión Financiera, Jurídica, Administrativa, Pogramas Salvación, Misión de Paz, Infraestructura, Psicosocial, | C21: 6.5 | E21: Entre 12 y 23 meses
A22: Dirección Ejecutiva Departamentos/estados Supervisión de Programas y proyectos y presupuestos. Responsabilidad por resultados en TODOS los programas y proyectos implementados en los municipios que conforman UN departamentos/estados específico | B22: Directores de Departamentos/estados/provincias, gestión de operaciones en el grupo de municipios del departamento | C22: 6.4 | E22: Entre 0 y 1 años | F22: 1
B23: Sudirectores de departamento. Seguimiento a la operación de los municipios del departamento | C23: 6.2 | E23: Entre 1 y 11 meses
B24: Directores de Programas y Áreas Seguimiento a las operaciones (Proyectos, salud, educación, infraestructura, Talento Humano, comunicaciones, Psicosocial, directores espirituales, capeyanes, etc… ) | C24: 6
A25: Equipo de profesionale vinculados a la gestión Continental Responsabilidad por los macroprocesos de UN área especifica en UNA macroregión determinada | B25: Profesionales Seguimiento a los macroprocesos de los países incluidos en la macroregión (América, Europa…) | C25: 6
A26: Dirección de Operaciones Municipales (Identificación de necesidades y recursos locales, construcción de proyectos, supervisión directa de planes de acción - metas e indicadores). Responsabilidad por Programas y Proyectos en UN municipio específico | B26: Directores Municipales, Responsables de los resultados de programas y proyectos en el municipio asignado. | C26: 6
B27: Subdirectores Municipales, | C27: 5.8
B28: Directores de Programas y Proyectos en el municipio Seguimiento a las operaciones (Proyectos, salud, educación, infraestructura, Talento Humano, comunicaciones, Psicosocial, directores espirituales, capeyanes, etc… ) | C28: 5.6
A29: Equipo de profesionales Gestion nacional. Responsabilidad por los macroprocesos de la gestión global en TODOS los continentes | B29: Equipos de profesionales de operaciones nacionales de Programas y Äreas, Proyecto ARCA | C29: 5.4
A30: Equipo de profesionales Gestion regional Responsabilidad por las operaciones de la gestión global en cada región | B30: Equipos de profesionales de operaciones regionales en cada país | C30: 5.2
A31: Equipo de profesionales Gestion Departamental/estadual. Responsabilidad por las operaciones de cada departamento | B31: Equipos de profesionales gestión en los departamentos | C31: 5
A32: Equipo de profesionales Gestion Municipal Responsabilidad por las operaciones de cada municipio | B32: Equipos de profesionales de operaciones en los muicipios (Psicólogos, promotores, médicos, maestros, evangelistas, consejeros, capeyanes) | C32: 4.8
A33: Equipo técnico y asistencial vinculado a la Gestión Global (todos los programas, proyecto y áreas en todos los continentes) | B33: Secretarias y personal administrativo gestion Global | C33: 4.6
B34: Personal Técnico / Operativo en gestión global | C34: 4.4
A35: Gestión Asistencial y técnica Continental (UNO o varios programas en UNA macroregión) | B35: Secretarias y personal administrativo macroregiones Continentes | C35: 4.2
B36: Personal Técnico / Operativo macroregiones - continental (macroregiones) | C36: 4
A37: Gestión Asistencia y técnica Nacional (Gestión de todos los Programas, Proyectos y äreas en UN país) | B37: Secretarias y personal administrativo Nacional | C37: 3.8
B38: Personal Técnico / Operativo en gestión Nacional | C38: 3.6
A39: Gestión Asistencial y técnica Regional (Gestión integral en varios departamentos de UNA región) | B39: Secretarias y personal administrativo regional | C39: 3.4
B40: Personal Técnico / Operativo en regiones país | C40: 3.2
A41: Gestión de Operaciones Departamentos/estadodos (gestión integral en varios municipios de UN departamento) | B41: Secretarias y personal administrativo departamentos | C41: 3
...

Sheet INSTRUCCIONES
A1: Columna1 | B1: Columna2
A2: No. | B2: GUÍA PARA DILIGENCIAR EL CONSOLIDADO INTERNACIONAL DE VOLUNTARIADO CERTIFICADO POR LOS LIDERES DE CADA ZONA - SE DEBE LEER ANTES DE INICIAR SU DILIGENCIAMIENTO
A3: 1 | B3: Se recomienda que solo debe ser diligenciado las líneas de color blanco, iniciando por la fila 4, y los títulos que solo se encuentran de color negro
A4: 2 | B4: Desde la fila dos en adelante, partiendo de las columnas A, B, C, D y E que corresponden a la Ubicación Geográfica, en estas celdas solo debe dar clip y aparece un al cual deberá pulsar y se despliega el nombre correspondiente a País, Departamento y Municipio
A5: 3 | B5: En la columna "A" corresponde a: "CONTINENTE", en esta celda deberá darle clip al nombre del continente en el cual se encuentra ubicado el país donde esta ejerciendo el voluntariado asignado, Ejemplo: Suramérica, Centroamérica, Europa, África, etc.
A6: 4 | B6: En la columna "B" corresponde a: "PAÍS", en esta celda deberá coloca el nombre del país donde se encuentra ubicado el área donde esta ejerciendo el voluntariado asignado, Ejemplo: Si el continente es: Suramérica, en el país: Colombia.
A7: 5 | B7: En la columna "C" corresponde a: "REGIÓN", en esta celda deberá pulsar la región donde queda ubicado el departamento donde ejerciendo el voluntariado asignado, según el caso en COLOMBIA: REGIÓN ANDINA, REGIÓN CARIBE, REGIÓN ORINOQUIA, REGIÓN PACIFICA, REGIÓN AMAZÓNICA y REGIÓN INSULAR , por Ejemplo: Si el continente es: Suramérica, en el país: Colombia, Región Atlántica, Departamento: Bolívar.
A8: 6 | B8: En la columna "D" corresponde a: "DEPARTAMENTO, PROVINCIA o ESTADO", en esta celda deberá coloca el nombre del Departamento, Provincia o Estado, según el caso de cada país, donde se encuentra ubicado la zona donde esta ejerciendo el voluntariado asignado, Ejemplo: Si el continente es: Suramérica, en el país: Colombia, en el Departamento: Bolívar.
A9: 7 | B9: En la columna "E" corresponde a: "MUNICIPIO", en esta celda deberá seleccionar el nombre del Municipio, según el caso de cada país, donde se encuentra ubicado el área donde esta ejerciendo el voluntariado asignado, Ejemplo: Si el continente es: Suramérica, en el país: Colombia, en el Departamento: Bolívar, el municipio: Arjona.
A10: 8 | B10: En la fila dos, de las columnas "F, G, H e I" corresponden a la "IDENTIFICACIÓN DEL VOLUNTARIO". Estas celdas deberán ser llenadas con los datos correspondiente a cada voluntario tal cual como aparece identificado en su documento de identidad, de acuerdo a la información requerida.
A11: 9 | B11: En la columna "J, K y L " corresponde al: "DATOS DE CONTACTO DEL VOLUNTARIO", en esta celda deberá colocar los datos requeridos correspondiente al siervo que esta sirviendo como voluntario.
A12: 10 | B12: En la columna "M" corresponde a la: "ASIGNACIÓN ACTUAL DEL VOLUNTARIO", en esta celda deberá colocar solo el nombre del Rol que le fue asignado
A13: 11 | B13: En las columnas "N, O, P Q y R" corresponde al: "ASIGNACIÓN Y TIEMPO DEL VOLUNTARIO EN LA FUNDACIÓN", esta celda se deberá hacerle un clip y aparecerá la asignación correspondiente a la cual usted deberá escoger, según la asignación ordenada, una ves escogida dicha asignación le aparecerá automáticamente el puntaje correspondiente (columna o), deberá pasar a las columnas: P y Q en las cuales deberá colocar la fecha en que inicio su voluntariado y si esta sirviendo en la actualidad en la fundación deberá colocar la fecha del día en que suministra los datos, estas fecha deben ser en formato: primero el día, después el mes y por ultimo el año, separados con un guion medio.
A14: 12 | B14: En la columnas "S y T " corresponde al: "TIEMPO DE PARTICIPACIÓN DEL VOLUNTARIO", en esta celda deberá darle clip a la celda y aparecerá unos rangos de tiempo en meses, para que usted escoja de acuerdo al tiempo real y verdadero que lleva sirviendo en la fundación.
... A16: 14 | B16: En las columnas "Z y AA" corresponde al: "NOMBRE DEL LIDER VOLUNTARIO, QUIEN REALIZO LA VALORACION", en esta celda deberá colocar el nombre del lider voluntario que hizo la valoracion, teniendo como criterio la veracidad y la realidad de su ejecucion, y en la siguiente columna debera colocar asignacion autorizada del lider voluntario y el sitio (nivel) donde desempeña dicho voluntariado.

Sheet DATOS
A1: Continente | B1: País | C1: Departamento | D1: Municipio | E1: DPTO. | G1: REGIONES | I1: R_ANDINA | K1: R_CARIBE | M1: R_PACÍFICA | O1: R_ORINOQUIA | Q1: R_AMAZONÍA | S1: R_INSULAR | U1: ANTIOQUIA | W1: ATLÁNTICO | Y1: BOGOTÁ | AA1: BOLÍVAR | AC1: BOYACÁ | AE1: CALDAS | AG1: CAQUETÁ | AI1: CAUCA | AK1: CESAR | AM1: CÓRDOBA | AO1: CUNDINAMARCA | AQ1: CHOCÓ | AS1: HUILA | AU1: LA_GUAJIRA | AW1: MAGDALENA | AY1: META | BA1: NARIÑO | BC1: N DE SANTANDER | BE1: QUINDÍO | BG1: RISARALDA | BI1: SANTANDER | BK1: SUCRE | BM1: TOLIMA | BO1: VALLE DEL C | BQ1: ARAUCA | BS1: CASANARE | BU1: PUTUMAYO | BW1: A. SAN ANDRÉS | BY1: AMAZONAS | CA1: GUAINÍA | CC1: GUAVIARE | CE1: VAUPÉS | CG1: VICHADA | CI1: TIPO DE IDENTIFICACION | CK1: TIEMPO Participación efectiva y continuada en las actividades de voluntariado) | CL1: PUNTAJE | CN1: TIEMPO Participación efectiva y continuada en las actividades de voluntariado) | CO1: PUNTAJE
A2: SUR AMÉRICA | B2: COLOMBIA | C2: ANTIOQUIA | D2: MEDELLÍN | E2: ANTIOQUIA | G2: R_ANDINA | I2: ANTIOQUIA | K2: ATLÁNTICO | M2: CHOCO | O2: ARAUCA | Q2: AMAZONAS | S2: SAN ANDRÉS | U2: MEDELLÍN | W2: BARRANQUILLA | Y2: BOGOTÁ D.C | AA2: CARTAGENA DE INDIAS | AC2: TUNJA | AE2: MANIZALES | AG2: FLORENCIA | AI2: POPAYÁN | AK2: VALLEDUPAR | AM2: MONTERÍA | AO2: AGUA DE DIOS | AQ2: QUIBDÓ | AS2: NEIVA | AU2: RIOHACHA | AW2: SANTA MARTA | AY2: VILLAVICENCIO | BA2: PASTO | BC2: CÚCUTA | BE2: ARMENIA | BG2: PEREIRA | BI2: BUCARAMANGA | BK2: SINCELEJO | BM2: IBAGUÉ | BO2: CALI | BQ2: ARAUCA | BS2: YOPAL | BU2: MOCOA | BW2: SAN ANDRÉS | BY2: LETICIA | CA2: INÍRIDA | CC2: SAN JOSÉ DEL GUAVIARE | CE2: MITÚ | CG2: PUERTO CARREÑO | CI2: CEDULA DE CIUDADANÍA (CC)
C3: ATLÁNTICO | D3: ABEJORRAL | E3: ANTIOQUIA | G3: R_CARIBE | I3: BOYACÁ | K3: BOLÍVAR | M3: VALLE_DEL_CAUCA | O3: CASANARE | Q3: CAQUETÁ | S3: PROVIDENCIA | U3: ABEJORRAL | W3: BARANOA | AA3: ACHÍ | AC3: ALMEIDA | AE3: AGUADAS | AG3: ALBANIA | AI3: ALMAGUER | AK3: AGUACHICA | AM3: AYAPEL | AO3: ALBÁN | AQ3: ACANDÍ | AS3: ACEVEDO | AU3: ALBANIA | AW3: ALGARROBO | AY3: ACACÍAS | BA3: ALBÁN | BC3: ÁBREGO | BE3: BUENAVISTA | BG3: APÍA | BI3: AGUADA | BK3: BUENAVISTA | BM3: ALPUJARRA | BO3: ALCALÁ | BQ3: ARAUQUITA | BS3: AGUAZUL | BU3: COLÓN | BW3: PROVIDENCIA | BY3: PUERTO NARIÑO | CC3: CALAMAR | CE3: CARURÚ | CG3: LA PRIMAVERA | CI3: PASAPORTE (PP) | CK3: 10 años o más | CL3: 10 | CN3: 10 años o más Mas de 120 meses | CO3: 10
C4: BOGOTÁ | D4: ABRIAQUÍ | E4: ANTIOQUIA | G4: R_PACÍFICA | I4: CALDAS | K4: CESAR | M4: CAUCA | O4: META | Q4: GUAINÍA | S4: SANTA CATALINA | U4: ABRIAQUÍ | W4: CAMPO DE LA CRUZ | AA4: ALTOS DEL ROSARIO | AC4: AQUITANIA | AE4: ANSERMA | AG4: BELÉN DE LOS ANDAQUÍES | AI4: ARGELIA | AK4: AGUSTÍN CODAZZI | AM4: BUENAVISTA | AO4: ANAPOIMA | AQ4: ALTO BAUDÓ | AS4: AGRADO | AU4: BARRANCAS | AW4: ARACATACA | AY4: BARRANCA DE UPÍA | BA4: ALDANA | BC4: ARBOLEDAS | BE4: CALARCÁ | BG4: BALBOA | BI4: ALBANIA | BK4: CAIMITO | BM4: ALVARADO | BO4: ANDALUCÍA | BQ4: CRAVO NORTE | BS4: CHÁMEZA | BU4: ORITO | CC4: EL RETORNO | CE4: TARAIRA | CG4: SANTA ROSALÍA | CI4: CEDULA DE IDENTIDAD (CI) | CK4: Entre 8 y 10 años | CL4: 9
C5: BOLÍVAR | D5: ALEJANDRÍA | E5: ANTIOQUIA | G5: R_ORINOQUIA | I5: CUNDINAMARCA | K5: CÓRDOBA | M5: NARIÑO | O5: VICHADA | Q5: GUAVIARE | U5: ALEJANDRÍA | W5: CANDELARIA | AA5: ARENAL | AC5: ARCABUCO | AE5: ARANZAZU | AG5: CARTAGENA DEL CHAIRÁ | AI5: BALBOA | AK5: ASTREA | AM5: CANALETE | AO5: ANOLAIMA | AQ5: ATRATO | AS5: AIPE | AU5: DIBULLA | AW5: ARIGUANÍ | AY5: CABUYARO | BA5: ANCUYÁ | BC5: BOCHALEMA | BE5: CIRCASIA | BG5: BELÉN DE UMBRÍA | BI5: ARATOCA | BK5: COLOSO | BM5: AMBALEMA | BO5: ANSERMANUEVO | BQ5: FORTUL | BS5: HATO COROZAL | BU5: PUERTO ASÍS | CC5: MIRAFLORES | CG5: CUMARIBO | CI5: DOCUMENTO NACIONAL DE IDENTIDAD (DNI) | CK5: Entre 7 y 8 años | CL5: 8 | CN5: 120
C6: BOYACÁ | D6: AMAGÁ | E6: ANTIOQUIA | G6: R_AMAZONÍA | I6: HUILA | K6: LA_GUAJIRA | Q6: PUTUMAYO | U6: AMAGÁ | W6: GALAPA | AA6: ARJONA | AC6: BELÉN | AE6: BELALCÁZAR | AG6: CURILLO | AI6: BOLÍVAR | AK6: BECERRIL | AM6: CERETÉ | AO6: ARBELÁEZ | AQ6: BAGADÓ | AS6: ALGECIRAS | AU6: DISTRACCIÓN | AW6: CERRO DE SAN ANTONIO | AY6: CASTILLA LA NUEVA | BA6: ARBOLEDA | BC6: BUCARASICA | BE6: CÓRDOBA | BG6: DOSQUEBRADAS | BI6: BARBOSA | BK6: COROZAL | BM6: ANZOÁTEGUI | BO6: ARGELIA | BQ6: PUERTO RONDÓN | BS6: LA SALINA | BU6: PUERTO CAICEDO | CI6: REGISTRO GERAL (RG) | CK6: Entre 6 y 7 años | CL6: 7 | CN6: Entre 8 y 10 años | CO6: 9
C7: CALDAS | D7: AMALFI | E7: ANTIOQUIA | G7: R_INSULAR | I7: NORTE_DE_SANTANDER | K7: MAGDALENA | Q7: VAUPÉS | U7: AMALFI | W7: JUAN DE ACOSTA | AA7: ARROYOHONDO | AC7: BERBEO | AE7: CHINCHINÁ | AG7: EL DONCELLO | AI7: BUENOS AIRES | AK7: BOSCONIA | AM7: CHIMÁ | AO7: BELTRÁN | AQ7: BAHÍA SOLANO | AS7: ALTAMIRA | AU7: EL MOLINO | AW7: CHIVOLO | AY7: SAN LUIS DE CUBARRAL | BA7: BARBACOAS | BC7: CÁCOTA | BE7: FILANDIA | BG7: GUÁTICA | BI7: BARICHARA | BK7: COVEÑAS | BM7: ARMERO GUAYABAL | BO7: BOLÍVAR | BQ7: SARAVENA | BS7: MANÍ | BU7: PUERTO GUZMÁN | CI7: CEDULA DE IDENTIDAD CIVIL (CIC) | CK7: Entre 5 y 6 años | CL7: 6 | CN7: Entre 96 y 120 meses
C8: CAQUETÁ | D8: ANDES | E8: ANTIOQUIA | I8: QUINDÍO | K8: SUCRE | U8: ANDES | W8: LURUACO | AA8: BARRANCO DE LOBA | AC8: BETÉITIVA | AE8: FILADELFIA | AG8: EL PAUJÍL | AI8: CAJIBÍO | AK8: CHIMICHAGUA | AM8: CHINÚ | AO8: BITUIMA | AQ8: BAJO BAUDÓ | AS8: BARAYA | AU8: FONSECA | AW8: CIÉNAGA | AY8: CUMARAL | BA8: BELÉN | BC8: CÁCHIRA | BE8: GÉNOVA | BG8: LA CELIA | BI8: BARRANCABERMEJA | BK8: CHALÁN | BM8: ATACO | BO8: BUENAVENTURA | BQ8: TAME | BS8: MONTERREY | BU8: PUERTO LEGUÍZAMO | CI8: CARNÉ DE IDENTIDAD (CI) | CK8: Entre 4 y 5 años | CL8: 5 | CN8: Entre 7 y 8 años | CO8: 8
C9: CAUCA | D9: ANGELÓPOLIS | E9: ANTIOQUIA | I9: RISARALDA | U9: ANGELÓPOLIS | W9: MALAMBO | AA9: CALAMAR | AC9: BOAVITA | AE9: LA DORADA | AG9: LA MONTAÑITA | AI9: CALDONO | AK9: CHIRIGUANÁ | AM9: CIÉNAGA DE ORO | AO9: BOJACÁ | AQ9: BOJAYÁ | AS9: CAMPOALEGRE | AU9: HATONUEVO | AW9: CONCORDIA | AY9: EL CALVARIO | BA9: BUESACO | BC9: CHINÁCOTA | BE9: LA TEBAIDA | BG9: LA VIRGINIA | BI9: BETULIA | BK9: EL ROBLE | BM9: CAJAMARCA | BO9: GUADALAJARA DE BUGA | BS9: NUNCHÍA | BU9: SIBUNDOY | CI9: DOCUMENTO ÚNICO DE IDENTIDAD (DUI) | CK9: Entre 3 y 4 años | CL9: 4 | CN9: Entre 84 y 95 meses
C10: CESAR | D10: ANGOSTURA | E10: ANTIOQUIA | I10: SANTANDER | U10: ANGOSTURA | W10: MANATÍ | AA10: CANTAGALLO | AC10: BOYACÁ | AE10: LA MERCED | AG10: MILÁN | AI10: CALOTO | AK10: CURUMANÍ | AM10: COTORRA | AO10: CABRERA | AQ10: EL CANTÓN DEL SAN PABLO | AS10: COLOMBIA | AU10: LA JAGUA DEL PILAR | AW10: EL BANCO | AY10: EL CASTILLO | BA10: COLÓN | BC10: CHITAGÁ | BE10: MONTENEGRO | BG10: MARSELLA | BI10: BOLÍVAR | BK10: GALERAS | BM10: CARMEN DE APICALÁ | BO10: BUGALAGRANDE | BS10: OROCUÉ | BU10: SAN FRANCISCO | CI10: DOCUMENTO PERSONAL DE IDENTIDAD (DPI) | CK10: Entre 2 y 3 años | CL10: 3 | CN10: Entre 6 y 7 años | CO10: 7
C11: CÓRDOBA | D11: ANORÍ | E11: ANTIOQUIA | I11: TOLIMA | U11: ANORÍ | W11: PALMAR DE VARELA | AA11: CICUCO | AC11: BRICEÑO | AE11: MANZANARES | AG11: MORELIA | AI11: CORINTO | AK11: EL COPEY | AM11: LA APARTADA | AO11: CACHIPAY | AQ11: CARMEN DEL DARIÉN | AS11: ELÍAS | AU11: MAICAO | AW11: EL PIÑÓN | AY11: EL DORADO | BA11: CONSACÁ | BC11: CONVENCIÓN | BE11: PIJAO | BG11: MISTRATÓ | BI11: CABRERA | BK11: GUARANDA | BM11: CASABIANCA | BO11: CAICEDONIA | BS11: PAZ DE ARIPORO | BU11: SAN MIGUEL | CI11: CEDULA DE IDENTIFICACIÓN PERSONAL (CIP) | CK11: Entre 1 y 2 años | CL11: 2 | CN11: Entre 72 y 83 meses
C12: CUNDINAMARCA | D12: SANTA FÉ DE ANTIOQUIA | E12: ANTIOQUIA | U12: SANTA FÉ DE ANTIOQUIA | W12: PIOJÓ | AA12: CÓRDOBA | AC12: BUENAVISTA | AE12: MARMATO | AG12: PUERTO RICO | AI12: EL TAMBO | AK12: EL PASO | AM12: LORICA | AO12: CAJICÁ | AQ12: CÉRTEGUI | AS12: GARZÓN | AU12: MANAURE | AW12: EL RETÉN | AY12: FUENTE DE ORO | BA12: CONTADERO | BC12: CUCUTILLA | BE12: QUIMBAYA | BG12: PUEBLO RICO | BI12: CALIFORNIA | BK12: LA UNIÓN | BM12: CHAPARRAL | BO12: CALIMA | BS12: PORE | BU12: SANTIAGO | CK12: Entre 0 y 1 años | CL12: 1 | CN12: Entre 5 y 6 años | CO12: 6
C13: CHOCÓ | D13: ANZÁ | E13: ANTIOQUIA | U13: ANZÁ | W13: POLONUEVO | AA13: CLEMENCIA | AC13: BUSBANZÁ | AE13: MARQUETALIA | AG13: SAN JOSÉ DEL FRAGUA | AI13: FLORENCIA | AK13: GAMARRA | AM13: LOS CÓRDOBAS | AO13: CAPARRAPÍ | AQ13: CONDOTO | AS13: GIGANTE | AU13: SAN JUAN DEL CESAR | AW13: FUNDACIÓN | AY13: GRANADA | BA13: CÓRDOBA | BC13: DURANIA | BE13: SALENTO | BG13: QUINCHÍA | BI13: CAPITANEJO | BK13: LOS PALMITOS | BM13: COELLO | BO13: CANDELARIA | BS13: RECETOR | BU13: VALLE DEL GUAMUEZ | CN13: Entre 60 y 71 meses
C14: HUILA | D14: APARTADÓ | E14: ANTIOQUIA | U14: APARTADÓ | W14: PONEDERA | AA14: EL CARMEN DE BOLÍVAR | AC14: CALDAS | AE14: MARULANDA | AG14: SAN VICENTE DEL CAGUÁN | AI14: GUACHENÉ | AK14: GONZÁLEZ | AM14: MOMIL | AO14: CÁQUEZA | AQ14: EL CARMEN DE ATRATO | AS14: GUADALUPE | AU14: URIBIA | AW14: GUAMAL | AY14: GUAMAL | BA14: CUASPÚD | BC14: EL CARMEN | BG14: SANTA ROSA DE CABAL | BI14: CARCASÍ | BK14: MAJAGUAL | BM14: COYAIMA | BO14: CARTAGO | BS14: SABANALARGA | BU14: VILLAGARZÓN | CN14: Entre 4 y 5 años | CO14: 5
C15: LA_GUAJIRA | D15: ARBOLETES | E15: ANTIOQUIA | U15: ARBOLETES | W15: PUERTO COLOMBIA | AA15: EL GUAMO | AC15: CAMPOHERMOSO | AE15: NEIRA | AG15: SOLANO | AI15: GUAPÍ | AK15: LA GLORIA | AM15: MONTELÍBANO | AO15: CARMEN DE CARUPA | AQ15: EL LITORAL DEL SAN JUAN | AS15: HOBO | AU15: URUMITA | AW15: NUEVA GRANADA | AY15: MAPIRIPÁN | BA15: CUMBAL | BC15: EL TARRA | BG15: SANTUARIO | BI15: CEPITÁ | BK15: MORROA | BM15: CUNDAY | BO15: DAGUA | BS15: SÁCAMA | CN15: Entre 48 y 59 meses
C16: MAGDALENA | D16: ARGELIA | E16: ANTIOQUIA | U16: ARGELIA | W16: REPELÓN | AA16: EL PEÑÓN | AC16: CERINZA | AE16: NORCASIA | AG16: SOLITA | AI16: INZÁ | AK16: LA JAGUA DE IBIRICO | AM16: MOÑITOS | AO16: CHAGUANÍ | AQ16: ISTMINA | AS16: ÍQUIRA | AU16: VILLANUEVA | AW16: PEDRAZA | AY16: MESETAS | BA16: CUMBITARA | BC16: EL ZULIA | BI16: CERRITO | BK16: OVEJAS | BM16: DOLORES | BO16: EL ÁGUILA | BS16: SAN LUIS DE PALENQUE | CN16: Entre 3 y 4 años | CO16: 4
C17: META | D17: ARMENIA | E17: ANTIOQUIA | U17: ARMENIA | W17: SABANAGRANDE | AA17: HATILLO DE LOBA | AC17: CHINAVITA | AE17: PÁCORA | AG17: VALPARAÍSO | AI17: JAMBALÓ | AK17: MANAURE BALCÓN DEL CESAR | AM17: PLANETA RICA | AO17: CHÍA | AQ17: JURADÓ | AS17: ISNOS | AW17: PIJIÑO DEL CARMEN | AY17: LA MACARENA | BA17: CHACHAGÜÍ | BC17: GRAMALOTE | BI17: CHARALÁ | BK17: PALMITO | BM17: ESPINAL | BO17: EL CAIRO | BS17: TÁMARA | CN17: Entre 36 y 47 meses
C18: NARIÑO | D18: BARBOSA | E18: ANTIOQUIA | U18: BARBOSA | W18: SABANALARGA | AA18: MAGANGUÉ | AC18: CHIQUINQUIRÁ | AE18: PALESTINA | AI18: LA SIERRA | AK18: PAILITAS | AM18: PUEBLO NUEVO | AO18: CHIPAQUE | AQ18: LLORÓ | AS18: LA ARGENTINA | AW18: PIVIJAY | AY18: URIBE | BA18: EL CHARCO | BC18: HACARÍ | BI18: CHARTA | BK18: SAMPUÉS | BM18: FALAN | BO18: EL CERRITO | BS18: TAURAMENA | CN18: Entre 2 y 3 años | CO18: 3
C19: NORTE_DE_SANTANDER | D19: BELMIRA | E19: ANTIOQUIA | U19: BELMIRA | W19: SANTA LUCÍA | AA19: MAHATES | AC19: CHISCAS | AE19: PENSILVANIA | AI19: LA VEGA | AK19: PELAYA | AM19: PUERTO ESCONDIDO | AO19: CHOACHÍ | AQ19: MEDIO ATRATO | AS19: LA PLATA | AW19: PLATO | AY19: LEJANÍAS | BA19: EL PEÑOL | BC19: HERRÁN | BI19: CHIMA | BK19: SAN BENITO ABAD | BM19: FLANDES | BO19: EL DOVIO | BS19: TRINIDAD | CN19: Entre 24 y 35 meses
C20: SUCRE | D20: BELLO | E20: ANTIOQUIA | U20: BELLO | W20: SANTO TOMÁS | AA20: MARGARITA | AC20: CHITA | AE20: RIOSUCIO | AI20: LÓPEZ DE MICAY | AK20: PUEBLO BELLO | AM20: PUERTO LIBERTADOR | AO20: CHOCONTÁ | AQ20: MEDIO BAUDÓ | AS20: NÁTAGA | AW20: PUEBLOVIEJO | AY20: PUERTO CONCORDIA | BA20: EL ROSARIO | BC20: LABATECA | BI20: CHIPATÁ | BK20: SAN JUAN DE BETULIA | BM20: FRESNO | BO20: FLORIDA | BS20: VILLANUEVA | CN20: Entre 1 y 2 años | CO20: 2
C21: QUINDIO | D21: BETANIA | E21: ANTIOQUIA | U21: BETANIA | W21: SOLEDAD | AA21: MARÍA LA BAJA | AC21: CHITARAQUE | AE21: RISARALDA | AI21: MERCADERES | AK21: RÍO DE ORO | AM21: PURÍSIMA DE LA CONCEPCIÓN | AO21: COGUA | AQ21: MEDIO SAN JUAN | AS21: OPORAPA | AW21: REMOLINO | AY21: PUERTO GAITÁN | BA21: EL TABLÓN DE GÓMEZ | BC21: LA ESPERANZA | BI21: CIMITARRA | BK21: SAN MARCOS | BM21: GUAMO | BO21: GINEBRA | CN21: Entre 12 y 23 meses
C22: RISARALDA | D22: BETULIA | E22: ANTIOQUIA | U22: BETULIA | W22: SUAN | AA22: MONTECRISTO | AC22: CHIVATÁ | AE22: SALAMINA | AI22: MIRANDA | AK22: LA PAZ | AM22: SAHAGÚN | AO22: COTA | AQ22: NÓVITA | AS22: PAICOL | AW22: SABANAS DE SAN ÁNGEL | AY22: PUERTO LÓPEZ | BA22: EL TAMBO | BC22: LA PLAYA | BI22: CONCEPCIÓN | BK22: SAN ONOFRE | BM22: HERVEO | BO22: GUACARÍ | CN22: Entre 0 y 1 años | CO22: 1
C23: SANTANDER | D23: CIUDAD BOLÍVAR | E23: ANTIOQUIA | U23: CIUDAD BOLÍVAR | W23: TUBARÁ | AA23: MOMPÓS | AC23: CIÉNEGA | AE23: SAMANÁ | AI23: MORALES | AK23: SAN ALBERTO | AM23: SAN ANDRÉS DE SOTAVENTO | AO23: CUCUNUBÁ | AQ23: NUQUÍ | AS23: PALERMO | AW23: SALAMINA | AY23: PUERTO LLERAS | BA23: FUNES | BC23: LOS PATIOS | BI23: CONFINES | BK23: SAN PEDRO | BM23: HONDA | BO23: JAMUNDÍ | CN23: Entre 1 y 11 meses
C24: TOLIMA | D24: BRICEÑO | E24: ANTIOQUIA | U24: BRICEÑO | W24: USIACURÍ | AA24: MORALES | AC24: CÓMBITA | AE24: SAN JOSÉ | AI24: PADILLA | AK24: SAN DIEGO | AM24: SAN ANTERO | AO24: EL COLEGIO | AQ24: RÍO IRÓ | AS24: PALESTINA | AW24: SAN SEBASTIÁN DE BUENAVISTA | AY24: PUERTO RICO | BA24: GUACHUCAL | BC24: LOURDES | BI24: CONTRATACIÓN | BK24: SAN LUIS DE SINCÉ | BM24: ICONONZO | BO24: LA CUMBRE
C25: VALLE DEL CAUCA | D25: BURITICÁ | E25: ANTIOQUIA | U25: BURITICÁ | AA25: NOROSÍ | AC25: COPER | AE25: SUPÍA | AI25: PÁEZ | AK25: SAN MARTÍN | AM25: SAN BERNARDO DEL VIENTO | AO25: EL PEÑÓN | AQ25: RÍO QUITO | AS25: PITAL | AW25: SAN ZENÓN | AY25: RESTREPO | BA25: GUAITARILLA | BC25: MUTISCUA | BI25: COROMORO | BK25: SUCRE | BM25: LÉRIDA | BO25: LA UNIÓN | CK25: TIEMPO Participación efectiva y continuada en las actividades de voluntariado) | CL25: PUNTAJE
C26: ARAUCA | D26: CÁCERES | E26: ANTIOQUIA | U26: CÁCERES | AA26: PINILLOS | AC26: CORRALES | AE26: VICTORIA | AI26: PATÍA | AK26: TAMALAMEQUE | AM26: SAN CARLOS | AO26: EL ROSAL | AQ26: RIOSUCIO | AS26: PITALITO | AW26: SANTA ANA | AY26: SAN CARLOS DE GUAROA | BA26: GUALMATÁN | BC26: OCAÑA | BI26: CURITÍ | BK26: SANTIAGO DE TOLÚ | BM26: LÍBANO | BO26: LA VICTORIA
C27: CASANARE | D27: CAICEDO | E27: ANTIOQUIA | U27: CAICEDO | AA27: REGIDOR | AC27: COVARACHÍA | AE27: VILLAMARÍA | AI27: PIAMONTE | AM27: SAN JOSÉ DE URÉ | AO27: FACATATIVÁ | AQ27: SAN JOSÉ DEL PALMAR | AS27: RIVERA | AW27: SANTA BÁRBARA DE PINTO | AY27: SAN JUAN DE ARAMA | BA27: ILES | BC27: PAMPLONA | BI27: EL CARMEN DE CHUCURÍ | BK27: TOLÚ VIEJO | BM27: SAN SEBASTIÁN DE MARIQUITA | BO27: OBANDO | CK27: 10 años o más | CL27: 10
C28: PUTUMAYO | D28: CALDAS | E28: ANTIOQUIA | U28: CALDAS | AA28: RÍO VIEJO | AC28: CUBARÁ | AE28: VITERBO | AI28: PIENDAMÓ | AM28: SAN PELAYO | AO28: FÓMEQUE | AQ28: SIPÍ | AS28: SALADOBLANCO | AW28: SITIONUEVO | AY28: SAN JUANITO | BA28: IMUÉS | BC28: PAMPLONITA | BI28: EL GUACAMAYO | BM28: MELGAR | BO28: PALMIRA | CK28: Entre 8 y 10 años | CL28: 9
C29: ARCHIPIÉLAGO DE SAN ANDRÉS, PROVIDENCIA Y SANTA CATALINA | D29: CAMPAMENTO | E29: ANTIOQUIA | U29: CAMPAMENTO | AA29: SAN CRISTÓBAL | AC29: CUCAITA | AI29: PUERTO TEJADA | AM29: TIERRALTA | AO29: FOSCA | AQ29: TADÓ | AS29: SAN AGUSTÍN | AW29: TENERIFE | AY29: SAN MARTÍN | BA29: IPIALES | BC29: PUERTO SANTANDER | BI29: EL PEÑÓN | BM29: MURILLO | BO29: PRADERA | CK29: Entre 7 y 8 años | CL29: 8
C30: AMAZONAS | D30: CAÑASGORDAS | E30: ANTIOQUIA | U30: CAÑASGORDAS | AA30: SAN ESTANISLAO | AC30: CUÍTIVA | AI30: PURACÉ | AM30: TUCHÍN | AO30: FUNZA | AQ30: UNGUÍA | AS30: SANTA MARÍA | AW30: ZAPAYÁN | AY30: VISTAHERMOSA | BA30: LA CRUZ | BC30: RAGONVALIA | BI30: EL PLAYÓN | BM30: NATAGAIMA | BO30: RESTREPO | CK30: Entre 6 y 7 años | CL30: 7
C31: GUAINÍA | D31: CARACOLÍ | E31: ANTIOQUIA | U31: CARACOLÍ | AA31: SAN FERNANDO | AC31: CHÍQUIZA | AI31: ROSAS | AM31: VALENCIA | AO31: FÚQUENE | AQ31: UNIÓN PANAMERICANA | AS31: SUAZA | AW31: ZONA BANANERA | BA31: LA FLORIDA | BC31: SALAZAR | BI31: ENCINO | BM31: ORTEGA | BO31: RIOFRÍO | CK31: Entre 5 y 6 años | CL31: 6
C32: GUAVIARE | D32: CARAMANTA | E32: ANTIOQUIA | U32: CARAMANTA | AA32: SAN JACINTO | AC32: CHIVOR | AI32: SAN SEBASTIÁN | AO32: FUSAGASUGÁ | AS32: TARQUI | BA32: LA LLANADA | BC32: SAN CALIXTO | BI32: ENCISO | BM32: PALOCABILDO | BO32: ROLDANILLO | CK32: Entre 4 y 5 años | CL32: 5
C33: VAUPÉS | D33: CAREPA | E33: ANTIOQUIA | U33: CAREPA | AA33: SAN JACINTO DEL CAUCA | AC33: DUITAMA | AI33: SANTANDER DE QUILICHAO | AO33: GACHALÁ | AS33: TESALIA | BA33: LA TOLA | BC33: SAN CAYETANO | BI33: FLORIÁN | BM33: PIEDRAS | BO33: SAN PEDRO | CK33: Entre 3 y 4 años | CL33: 4
C34: VICHADA | D34: EL CARMEN DE VIBORAL | E34: ANTIOQUIA | U34: EL CARMEN DE VIBORAL | AA34: SAN JUAN NEPOMUCENO | AC34: EL COCUY | AI34: SANTA ROSA | AO34: GACHANCIPÁ | AS34: TELLO | BA34: LA UNIÓN | BC34: SANTIAGO | BI34: FLORIDABLANCA | BM34: PLANADAS | BO34: SEVILLA | CK34: Entre 2 y 3 años | CL34: 3
D35: CAROLINA | E35: ANTIOQUIA | U35: CAROLINA | AA35: SAN MARTÍN DE LOBA | AC35: EL ESPINO | AI35: SILVIA | AO35: GACHETÁ | AS35: TERUEL | BA35: LEIVA | BC35: SARDINATA | BI35: GALÁN | BM35: PRADO | BO35: TORO | CK35: Entre 1 y 2 años | CL35: 2
D36: CAUCASIA | E36: ANTIOQUIA | U36: CAUCASIA | AA36: SAN PABLO | AC36: FIRAVITOBA | AI36: SOTARA | AO36: GAMA | AS36: TIMANÁ | BA36: LINARES | BC36: SILOS | BI36: GÁMBITA | BM36: PURIFICACIÓN | BO36: TRUJILLO | CK36: Entre 0 y 1 años | CL36: 1
D37: CHIGORODÓ | E37: ANTIOQUIA | U37: CHIGORODÓ | AA37: SANTA CATALINA | AC37: FLORESTA | AI37: SUÁREZ | AO37: GIRARDOT | AS37: VILLAVIEJA | BA37: LOS ANDES | BC37: TEORAMA | BI37: GIRÓN | BM37: RIOBLANCO | BO37: TULUÁ
D38: CISNEROS | E38: ANTIOQUIA | U38: CISNEROS | AA38: SANTA ROSA | AC38: GACHANTIVÁ | AI38: SUCRE | AO38: GRANADA | AS38: YAGUARÁ | BA38: MAGÜÍ | BC38: TIBÚ | BI38: GUACA | BM38: RONCESVALLES | BO38: ULLOA
D39: COCORNÁ | E39: ANTIOQUIA | U39: COCORNÁ | AA39: SANTA ROSA DEL SUR | AC39: GÁMEZA | AI39: TIMBÍO | AO39: GUACHETÁ | BA39: MALLAMA | BC39: TOLEDO | BI39: GUADALUPE | BM39: ROVIRA | BO39: VERSALLES | CK39: Entre 96 y 120 meses
D40: CONCEPCIÓN | E40: ANTIOQUIA | U40: CONCEPCIÓN | AA40: SIMITÍ | AC40: GARAGOA | AI40: TIMBIQUÍ | AO40: GUADUAS | BA40: MOSQUERA | BC40: VILLA CARO | BI40: GUAPOTÁ | BM40: SALDAÑA | BO40: VIJES | CK40: Entre 84 y 95 meses
...

Sheet VALORACION
A1: VALORACIÓN DE LA GESTIÓN DEL VOLUNTARIO
A2: PARTICIPACIÓN (En el Altar de Oración 24/7, en actividades para la unidad espiritual, en capacitaciones, en gestión social, en planeación) | B2: PUNTAJE | C2: COMPROMISO (Disposición y disponibilidad para asumir responsabilidades y entregar resultados de manera oportuna y eficaz) | D2: PUNTAJE | F2: TIEMPO Participación efectiva y continuada en las actividades de voluntariado) | G2: PUNTAJE
A3: Participación excepcional, motor clave del equipo | B3: 10 | C3: Compromiso excepcional, modelo de fidelidad y entrega | D3: 10
A4: Participación sobresaliente, liderazgo activo | B4: 9 | C4: Compromiso ejemplar, referente para otros | D4: 9 | F4: Desde 120 meses o más | G4: 10
A5: Participación alta, proactiva y comprometida | B5: 8 | C5: Compromiso alto, constante y fiel | D5: 8 | F5: Entre 96 meses y 119 meses | G5: 9
A6: Buena participación, colabora con constancia | B6: 7 | C6: Buen compromiso, responsable y confiable | D6: 7 | F6: Entre 84 meses y 95 meses | G6: 8
A7: Participa activamente en algunas actividades | B7: 6 | C7: Compromiso aceptable, responde cuando se le solicita | D7: 6 | F7: Entre 72 meses y 83 meses | G7: 7
A8: Participación regular, cumple lo básico | B8: 5 | C8: Compromiso básico, cumple lo mínimo esperado | D8: 5 | F8: Entre 60 meses y 71 meses | G8: 6
A9: Participa ocasionalmente, requiere motivación externa | B9: 4 | C9: Compromiso débil, cumple parcialmente | D9: 4 | F9: Entre 48 meses y 59 meses | G9: 5
A10: Participación baja e inconstante | B10: 3 | C10: Compromiso bajo, requiere constante supervisión | D10: 3 | F10: Entre 36 meses y 47 meses | G10: 4
A11: Participa muy rara vez, mínima interacción | B11: 2 | C11: Compromiso deficiente, irresponsabilidad frecuente | D11: 2 | F11: Entre 24 meses y 35 meses | G11: 3
A12: Casi nunca participa, ausencias constantes | B12: 1 | C12: Compromiso muy bajo evidenciado en incumplimientos reiterados | D12: 1 | F12: Entre 12 meses y 23 meses | G12: 2
F13: Menos de 12 meses | G13: 1
H16: 10 años o más Mas de 120 meses
H18: 120
H19: Entre 8 y 10 años
H20: Entre 96 y 120 meses
H21: Entre 7 y 8 años
H22: Entre 84 y 95 meses
H23: Entre 6 y 7 años
H24: Entre 72 y 83 meses
H25: Entre 5 y 6 años
H26: Entre 60 y 71 meses
H27: Entre 4 y 5 años
H28: Entre 48 y 59 meses
H29: Entre 3 y 4 años
H30: Entre 36 y 47 meses
... H36: Entre 1 y 11 meses
